test_add_1 (unitMymath.unitMymath) ... FAIL
test_add_2 (unitMymath.unitMymath) ... ok
test_add_3 (unitMymath.unitMymath) ... ok

======================================================================
FAIL: test_add_1 (unitMymath.unitMymath)
----------------------------------------------------------------------
Traceback (most recent call last):
  File "C:\Users\Administrator\Desktop\apli\15_Unittest\unitMymath.py", line 34, in test_add_1
    self.assertIsNotNone(expectValue,"是空的")
AssertionError: unexpectedly None : 是空的

----------------------------------------------------------------------
Ran 3 tests in 0.009s

FAILED (failures=1)
