test_add_1 (unitMymath.unitMymath) ... FAIL
test_add_2 (unitMymath.unitMymath) ... ok
test_add_3 (unitMymath.unitMymath) ... ok

======================================================================
FAIL: test_add_1 (unitMymath.unitMymath)
----------------------------------------------------------------------
Traceback (most recent call last):
  File "C:\Users\Administrator\Desktop\apli\15_Unittest\unitMymath.py", line 30, in test_add_1
    self.assertTrue(False)
AssertionError: False is not true

----------------------------------------------------------------------
Ran 3 tests in 0.003s

FAILED (failures=1)
