test_add_1 (unitMymath.unitMymath) ... FAIL
test_add_2 (unitMymath.unitMymath) ... ok
test_add_3 (unitMymath.unitMymath) ... ok

======================================================================
FAIL: test_add_1 (unitMymath.unitMymath)
----------------------------------------------------------------------
Traceback (most recent call last):
  File "C:\Users\Administrator\Desktop\apli\15_Unittest\unitMymath.py", line 29, in test_add_1
    self.assertEqual(actualValue,expectValue,"预期结果与实际不相符")
AssertionError: 22 != 21 : 预期结果与实际不相符

----------------------------------------------------------------------
Ran 3 tests in 0.004s

FAILED (failures=1)
